Workbook

Sheet Guide
A1: PIADE Packaging OEE - Lean Six Sigma DMAIC Workbook
A2: Data: PIADE (Kaggle) 5 packaging machines, 429,394 state intervals, Jan 2020 - Dec 2021. Heavy lifting in PostgreSQL (sql/ folder); this workbook = analysis + decisions.
A4: Phase | B4: Question it answers | C4: Tabs in this workbook | D4: PostgreSQL views | E4: Tools used | F4: Tollgate deliverable
A5: DEFINE | B5: What problem, for whom, how big, what goal? | C5: D1_Charter, D2_SIPOC, D3_VOC_CTQ | D5: v_oee_summary (baseline) | E5: Project charter, SIPOC, VOC->CTQ tree | F5: Signed charter with SMART goal
A6: MEASURE | B6: How good is the process today, and can we trust the data? | C6: Inputs, M1_DataQuality, M2_OEE, M3_LossTree, M4_Pareto, M5_Reliability, M6_Sigma | D6: v_data_quality, v_daily_machine, v_oee_summary, v_loss_tree, v_pareto_alarm, v_reliability | E6: Data collection plan, MSA (integrity checks), OEE, loss tree, Pareto, MTBF/MTTR, DPMO/sigma | F6: Validated baseline: OEE 51.7%, loss tree, vital few
A7: ANALYZE | B7: Which causes actually drive the losses? | C7: A1_RCA, A2_FMEA, A3_Hypothesis | D7: v_shift_state_share, v_alarm_shift_crosstab, v_fmea_inputs, v_hourly_profile | E7: Fishbone (6M), 5 Whys, data-driven FMEA, ANOVA, Welch t, chi-square, regression | F7: Verified root causes (data vs hypothesis)
A8: IMPROVE | B8: What do we change, and what is it worth? | C8: I1_Solutions, I2_OEE_Scenario, I3_SMED, I4_PokaYoke, I5_5S_Audit, I6_Kaizen, I7_Kanban, I8_Inventory | D8: v_smed_baseline, v_kanban, v_material_demand, v_inventory_policy | E8: Solution matrix, SMED, Poka-Yoke, 5S, Kaizen/PDCA, Kanban, VSM future state, SS/ROP/EOQ | F8: Prioritised plan + projected OEE bridge
A9: CONTROL | B9: How do we hold the gain? | C9: C1_XbarR_s1, C2_Capability, C3_ControlPlan, C4_OCAP | D9: v_xbar_r_subgroups, v_xbar_r_limits, v_xbar_r_chart, v_capability | E9: X-bar & R chart, Cpk/Ppk, control plan, OCAP, Power BI cockpit | F9: Control plan handed to process owner
A11: Colour code
A12: 1234 | B12: Blue text = hard-coded input / SQL extract value
A13: =1+1 -> 2 | B13: Black text = formula on this sheet
A14: =Inputs!B5 -> 0.65 | B14: Green text = formula linking another sheet
A15: 0.65 | B15: Yellow fill = assumption / cell you may edit (everything recalculates)
A17: Refresh cycle | B17: 1) run sql/01 + sql/02 in PostgreSQL 2) run sql/03_export.sql 3) paste the CSVs into the Data_* tabs 4) all tabs recalculate

Sheet Inputs
A1: Inputs & assumptions (edit yellow cells only)
A2: Every hard-coded assumption lives here and is referenced by formulas elsewhere.
A4: Parameter | B4: Value | C4: Unit | D4: Source / note
A5: OEE target (project goal) | B5: 0.65 | C5: fraction | D5: Project goal; world-class benchmark is 0.85
A6: Quality LSL (daily good / total) | B6: 0.99 | C6: fraction | D6: Assumed customer requirement
A7: Contribution per good pack | B7: 0.6 | C7: INR | D7: ASSUMPTION - replace with finance data
A8: Study period | B8: 2 | C8: years | D8: Jan 2020 - Dec 2021 (731 days)
A9: Packaging blank unit cost | B9: 4 | C9: INR | D9: ASSUMPTION
A10: Ordering cost per PO | B10: 6000 | C10: INR | D10: ASSUMPTION
A11: Annual holding rate | B11: 0.24 | C11: fraction | D11: ASSUMPTION (capital + storage + obsolescence)
A12: Supplier lead time | B12: 7 | C12: days | D12: ASSUMPTION
A13: Lead-time standard deviation | B13: 1.5 | C13: days | D13: ASSUMPTION
A14: Target cycle service level | B14: 0.98 | C14: fraction | D14: Policy choice
A15: Kanban container quantity | B15: 2000 | C15: blanks/bin | D15: ASSUMPTION
A16: Kanban replenishment lead time | B16: 8 | C16: hours | D16: ASSUMPTION (one shift)
... A23: Spare-kit holding rate | B23: 0.2 | C23: fraction | D23: ASSUMPTION

Sheet D1_Charter
A1: D1 - Project charter
A2: DEFINE. Baseline numbers are live formulas from the Measure tabs.
A4: Element | B4: Content
A5: Project title | B5: Raise OEE of the packaging-machine fleet (PIADE s_1..s_5) through Lean Six Sigma
A6: Problem statement | B6: ="Between Jan-2020 and Dec-2021 the 5 packaging machines ran at a fleet OEE of "&TEXT(M2_OEE!O10,"0.0%")&" against a "&TEXT(Inputs!B5,"0%")&" target. "&TEXT(M2_OEE!G10/M2_OEE!D10,"0%")&" of planned time was idle with no reason code and "&TEXT(M2_OEE!F10/M2_OEE!D10,"0.0%")&" was lost to "&TEXT(M5_Reliability!B10,"#,##0")&" alarm stops. s_1, the highest-volume machine, is the only one whose OEE fell in 2021." -> Between Jan-2020 and Dec-2021 the 5 packaging machines ran at a fleet OEE of 51.7% against a 65% target. 27% of planned time was idle with no reason code and 8.4% was lost to 92,005 alarm stops. s_1, the highest-volume machine, is the only one whose OEE fell in 2021.
A7: Business case | B7: ="Every OEE point is worth ~"&TEXT(M2_OEE!D10/Inputs!B8*M2_OEE!I10/M2_OEE!E10*0.01,"#,##0")&" good packs/year (~INR "&TEXT(M2_OEE!D10/Inputs!B8*M2_OEE!I10/M2_OEE!E10*0.01*Inputs!B7/100000,"0.0")&" lakh contribution at the assumed margin)." -> Every OEE point is worth ~919,720 good packs/year (~INR 5.5 lakh contribution at the assumed margin).
A8: Goal (SMART) | B8: ="Raise fleet OEE from "&TEXT(M2_OEE!O10,"0.0%")&" to >= 60% (stretch "&TEXT(Inputs!B5,"0%")&") within 6 months of go-live, while holding quality >= 99.5% and packaging-material service level >= 98%." -> Raise fleet OEE from 51.7% to >= 60% (stretch 65%) within 6 months of go-live, while holding quality >= 99.5% and packaging-material service level >= 98%.
A9: Primary metric (Y) | B9: OEE = Availability x Performance x Quality (TPM definition; idle counts as availability loss)
A10: Secondary metrics | B10: Alarm downtime hours (vital-few codes), idle share by shift, changeover minutes, material stock-outs, safety-stock value
A11: In scope | B11: Machines s_1..s_5; alarm stops, idle, speed loss, changeovers; line-side packaging-material supply
A12: Out of scope | B12: Upstream filling / downstream palletising; capex machine redesign; product-mix planning
A13: Pilot | B13: s_1 (33% of fleet volume, largest single loss A_065, only machine that degraded in 2021)
A14: Team (fill in) | B14: Sponsor: Plant head | Champion: Packaging manager | Black/Green Belt: <you> | Members: shift leads, maintenance, stores, quality
A15: Timeline | B15: Define wk 1-2 | Measure wk 3-5 | Analyze wk 6-8 | Improve wk 9-16 (pilot s_1) | Control wk 17-24
A16: Honesty note | B16: Retrospective study on a public dataset: Improve results are PROJECTIONS using assumed reduction rates, not measured outcomes.

Sheet D2_SIPOC
A1: D2 - SIPOC
A2: DEFINE. High-level map of the packaging process.
A4: Suppliers | B4: Inputs | C4: Process (high level) | D4: Outputs | E4: Customers
A5: Film / carton suppliers | B5: Carton blanks, film, glue | C5: 1. Receive & store packaging material | D5: Packed units (po) | E5: Distribution centre
A6: Upstream filling line | B6: Product units to pack (pi) | C6: 2. Stage material line-side (Kanban) | D6: Rejects (pi - po) | E6: Sales / key accounts
A7: Maintenance | B7: Machine availability, spares | C7: 3. Changeover / set-up (SMED) | D7: Alarm & state logs | E7: Quality / QA
A8: Planning (S&OP) | B8: Schedule, set speed | C8: 4. Run & pack at rated speed | D8: OEE, downtime data | E8: Plant management
A9: Operators (3 shifts) | B9: Skills, standard work | C9: 5. Stop recovery / restart | D9: Changeover records | E9: Finance (COPQ)
A10: IT / MES | B10: State + counter logging | C10: 6. Record, review, improve | D10: Dashboards | E10: Continuous-improvement team

Sheet D3_VOC_CTQ
A1: D3 - Voice of customer -> CTQ tree
A2: DEFINE. Translate vague needs into measurable CTQs with specs.
A4: Voice of customer / business | B4: Driver | C4: CTQ (measurable) | D4: Operational definition | E4: Target / spec | F4: Baseline (live)
A5: 'We never ship full orders on time' | B5: Capacity | C5: OEE (fleet) | D5: Run/PPT x Output/Ideal x Good/Output | E5: ="LSL "&TEXT(Inputs!B5,"0%") -> LSL 65% | F5: =M2_OEE!O10 -> 0.51736506
A6: 'The line keeps stopping' | B6: Availability | C6: Alarm downtime share | D6: Downtime h / planned h | E6: <= 6% | F6: =M2_OEE!F10/M2_OEE!D10 -> 0.083716532
A7: 'Nobody is at the machine at night' | B7: Availability | C7: Idle share | D7: Idle h / planned h | E7: <= 20% | F7: =M2_OEE!G10/M2_OEE!D10 -> 0.27305744
A8: 'It runs slow' | B8: Performance | C8: Performance rate | D8: Units in / ideal units at rated speed | E8: >= 88% | F8: =M2_OEE!M10 -> 0.80763044
A9: 'Too many damaged packs' | B9: Quality | C9: Quality rate | D9: Units out / units in | E9: =">= "&TEXT(Inputs!B6,"0.0%") -> >= 99.0% | F9: =M2_OEE!N10 -> 0.99591163
A10: 'Changeovers take forever' | B10: Flexibility | C10: Mean changeover minutes | D10: Planned stop 10 min - 4 h | E10: -40% vs baseline | F10: =I3_SMED!C10 -> 51.368459
A11: 'We run out of cartons' | B11: Supply | C11: Cycle service level | D11: Order cycles without stock-out | E11: =">= "&TEXT(Inputs!B14,"0%") -> >= 98% | F11: see I8_Inventory

Sheet M1_DataQuality
A1: M1 - Data collection plan & data integrity (MSA substitute)
A2: MEASURE. Machine logs cannot be re-measured, so a Gage R&R is replaced by integrity checks (results from v_data_quality).
A4: Integrity check | B4: Result | C4: Interpretation
A5: rows loaded | B5: 429394 | C5: Complete load
A6: null cells in key columns | B6: 0 | C6: OK
A7: duplicate rows | B7: 0 | C7: OK
A8: elapsed vs (end-start) mismatch > 1 % | B8: 0 | C8: OK
A9: negative counter deltas (pi) | B9: 85 | C9: Counter resets -> excluded
A10: counter deltas rejected as glitch | B10: 2397 | C10: Counter delta > 3x theoretical -> excluded (0.6%)
A11: alarm on non-downtime row | B11: 0 | C11: OK
A12: downtime row without alarm | B12: 0 | C12: OK
A13: idle rows with a reason code | B13: 0 | C13: GAP: idle is never explained -> Control-phase fix
A16: Metric | B16: Operational definition | C16: Source field(s) | D16: SQL view | E16: Frequency | F16: Unit
A17: Planned production time | B17: Logged time minus scheduled_downtime | C17: type, elapsed (ms) | D17: v_daily_machine | E17: Daily / shift | F17: h
A18: Run time | B18: Time in production + performance_loss | C18: type, elapsed | D18: v_daily_machine | E18: Daily / shift | F18: h
A19: Units in / out | B19: Delta of cumulative counters pi / po (read at interval end) | C19: pi, po | D19: f_interval (LAG) | E19: Per interval | F19: packs
A20: Ideal units | B20: Rated speed x run time | C20: speed, elapsed | D20: v_daily_machine | E20: Daily | F20: packs
A21: Stop event | B21: Consecutive downtime rows, same alarm, same machine | C21: alarm, type | D21: f_downtime_event | E21: Per event | F21: count, min
A22: Shift | B22: A 06-14, B 14-22, C 22-06 (UTC, assumed) | C22: interval_start | D22: f_interval | E22: Per interval | F22: -
A23: Production day | B23: 06:00 to 06:00 (keeps a night shift in one day) | C23: interval_start | D23: f_interval | E23: Per interval | F23: date

Sheet M2_OEE
A1: M2 - Baseline OEE by machine
A2: MEASURE. SUMIF over Data_Daily (SQL extract of v_daily_machine). OEE = A x P x Q.
A4: Machine | B4: Logged h | C4: Scheduled h | D4: Planned h | E4: Run h | F4: Alarm downtime h | G4: Idle h | H4: Perf-loss state h | I4: Ideal units | J4: Units in | K4: Units out | L4: Availability | M4: Performance | N4: Quality | O4: OEE | P4: Gap to target (pts) | Q4: Utilization (run/logged)
A5: s_1 | B5: =SUMIF(Data_Daily!$A$2:$A$2407,$A5,Data_Daily!$C$2:$C$2407)/3600 -> 13458.096 | C5: =SUMIF(Data_Daily!$A$2:$A$2407,$A5,Data_Daily!$D$2:$D$2407)/3600 -> 1552.0647 | D5: =SUMIF(Data_Daily!$A$2:$A$2407,$A5,Data_Daily!$E$2:$E$2407)/3600 -> 11906.031 | E5: =SUMIF(Data_Daily!$A$2:$A$2407,$A5,Data_Daily!$F$2:$F$2407)/3600 -> 9245.5438 | F5: =SUMIF(Data_Daily!$A$2:$A$2407,$A5,Data_Daily!$I$2:$I$2407)/3600 -> 1393.3596 | G5: =SUMIF(Data_Daily!$A$2:$A$2407,$A5,Data_Daily!$J$2:$J$2407)/3600 -> 1267.1278 | H5: =SUMIF(Data_Daily!$A$2:$A$2407,$A5,Data_Daily!$H$2:$H$2407)/3600 -> 1540.7381 | I5: =SUMIF(Data_Daily!$A$2:$A$2407,$A5,Data_Daily!$K$2:$K$2407) -> 37086522 | J5: =SUMIF(Data_Daily!$A$2:$A$2407,$A5,Data_Daily!$L$2:$L$2407) -> 31286632 | K5: =SUMIF(Data_Daily!$A$2:$A$2407,$A5,Data_Daily!$M$2:$M$2407) -> 31148051 | L5: =E5/D5 -> 0.77654288 | M5: =MIN(J5/I5,1) -> 0.84361192 | N5: =K5/J5 -> 0.9955706 | O5: =L5*M5*N5 -> 0.65219913 | P5: =(O5-Inputs!$B$5)*100 -> 0.21991283 | Q5: =E5/B5 -> 0.68698751
A6: s_2 | B6: =SUMIF(Data_Daily!$A$2:$A$2407,$A6,Data_Daily!$C$2:$C$2407)/3600 -> 5532.4767 | C6: =SUMIF(Data_Daily!$A$2:$A$2407,$A6,Data_Daily!$D$2:$D$2407)/3600 -> 1369.1251 | D6: =SUMIF(Data_Daily!$A$2:$A$2407,$A6,Data_Daily!$E$2:$E$2407)/3600 -> 4163.3515 | E6: =SUMIF(Data_Daily!$A$2:$A$2407,$A6,Data_Daily!$F$2:$F$2407)/3600 -> 1719.7614 | F6: =SUMIF(Data_Daily!$A$2:$A$2407,$A6,Data_Daily!$I$2:$I$2407)/3600 -> 573.78872 | G6: =SUMIF(Data_Daily!$A$2:$A$2407,$A6,Data_Daily!$J$2:$J$2407)/3600 -> 1869.8014 | H6: =SUMIF(Data_Daily!$A$2:$A$2407,$A6,Data_Daily!$H$2:$H$2407)/3600 -> 363.36303 | I6: =SUMIF(Data_Daily!$A$2:$A$2407,$A6,Data_Daily!$K$2:$K$2407) -> 10628003 | J6: =SUMIF(Data_Daily!$A$2:$A$2407,$A6,Data_Daily!$L$2:$L$2407) -> 8337448 | K6: =SUMIF(Data_Daily!$A$2:$A$2407,$A6,Data_Daily!$M$2:$M$2407) -> 8292863 | L6: =E6/D6 -> 0.41307139 | M6: =MIN(J6/I6,1) -> 0.78447924 | N6: =K6/J6 -> 0.99465244 | O6: =L6*M6*N6 -> 0.32231308 | P6: =(O6-Inputs!$B$5)*100 -> -32.768692 | Q6: =E6/B6 -> 0.31084838
A7: s_3 | B7: =SUMIF(Data_Daily!$A$2:$A$2407,$A7,Data_Daily!$C$2:$C$2407)/3600 -> 7450.6406 | C7: =SUMIF(Data_Daily!$A$2:$A$2407,$A7,Data_Daily!$D$2:$D$2407)/3600 -> 690.68448 | D7: =SUMIF(Data_Daily!$A$2:$A$2407,$A7,Data_Daily!$E$2:$E$2407)/3600 -> 6759.9561 | E7: =SUMIF(Data_Daily!$A$2:$A$2407,$A7,Data_Daily!$F$2:$F$2407)/3600 -> 3326.6326 | F7: =SUMIF(Data_Daily!$A$2:$A$2407,$A7,Data_Daily!$I$2:$I$2407)/3600 -> 466.29693 | G7: =SUMIF(Data_Daily!$A$2:$A$2407,$A7,Data_Daily!$J$2:$J$2407)/3600 -> 2967.0266 | H7: =SUMIF(Data_Daily!$A$2:$A$2407,$A7,Data_Daily!$H$2:$H$2407)/3600 -> 305.30328 | I7: =SUMIF(Data_Daily!$A$2:$A$2407,$A7,Data_Daily!$K$2:$K$2407) -> 13259061 | J7: =SUMIF(Data_Daily!$A$2:$A$2407,$A7,Data_Daily!$L$2:$L$2407) -> 11927022 | K7: =SUMIF(Data_Daily!$A$2:$A$2407,$A7,Data_Daily!$M$2:$M$2407) -> 11898514 | L7: =E7/D7 -> 0.4921086 | M7: =MIN(J7/I7,1) -> 0.89953746 | N7: =K7/J7 -> 0.9976098 | O7: =L7*M7*N7 -> 0.44161205 | P7: =(O7-Inputs!$B$5)*100 -> -20.838795 | Q7: =E7/B7 -> 0.44648947
A8: s_4 | B8: =SUMIF(Data_Daily!$A$2:$A$2407,$A8,Data_Daily!$C$2:$C$2407)/3600 -> 7350.8911 | C8: =SUMIF(Data_Daily!$A$2:$A$2407,$A8,Data_Daily!$D$2:$D$2407)/3600 -> 1219.3629 | D8: =SUMIF(Data_Daily!$A$2:$A$2407,$A8,Data_Daily!$E$2:$E$2407)/3600 -> 6131.5282 | E8: =SUMIF(Data_Daily!$A$2:$A$2407,$A8,Data_Daily!$F$2:$F$2407)/3600 -> 4238.2206 | F8: =SUMIF(Data_Daily!$A$2:$A$2407,$A8,Data_Daily!$I$2:$I$2407)/3600 -> 358.38358 | G8: =SUMIF(Data_Daily!$A$2:$A$2407,$A8,Data_Daily!$J$2:$J$2407)/3600 -> 1534.9241 | H8: =SUMIF(Data_Daily!$A$2:$A$2407,$A8,Data_Daily!$H$2:$H$2407)/3600 -> 1540.1006 | I8: =SUMIF(Data_Daily!$A$2:$A$2407,$A8,Data_Daily!$K$2:$K$2407) -> 23527932 | J8: =SUMIF(Data_Daily!$A$2:$A$2407,$A8,Data_Daily!$L$2:$L$2407) -> 15357768 | K8: =SUMIF(Data_Daily!$A$2:$A$2407,$A8,Data_Daily!$M$2:$M$2407) -> 15250883 | L8: =E8/D8 -> 0.69121766 | M8: =MIN(J8/I8,1) -> 0.6527462 | N8: =K8/J8 -> 0.99304033 | O8: =L8*M8*N8 -> 0.44804957 | P8: =(O8-Inputs!$B$5)*100 -> -20.195043 | Q8: =E8/B8 -> 0.57655875
A9: s_5 | B9: =SUMIF(Data_Daily!$A$2:$A$2407,$A9,Data_Daily!$C$2:$C$2407)/3600 -> 10338.45 | C9: =SUMIF(Data_Daily!$A$2:$A$2407,$A9,Data_Daily!$D$2:$D$2407)/3600 -> 1702.962 | D9: =SUMIF(Data_Daily!$A$2:$A$2407,$A9,Data_Daily!$E$2:$E$2407)/3600 -> 8635.4876 | E9: =SUMIF(Data_Daily!$A$2:$A$2407,$A9,Data_Daily!$F$2:$F$2407)/3600 -> 5652.7956 | F9: =SUMIF(Data_Daily!$A$2:$A$2407,$A9,Data_Daily!$I$2:$I$2407)/3600 -> 355.60755 | G9: =SUMIF(Data_Daily!$A$2:$A$2407,$A9,Data_Daily!$J$2:$J$2407)/3600 -> 2627.0845 | H9: =SUMIF(Data_Daily!$A$2:$A$2407,$A9,Data_Daily!$H$2:$H$2407)/3600 -> 1043.3275 | I9: =SUMIF(Data_Daily!$A$2:$A$2407,$A9,Data_Daily!$K$2:$K$2407) -> 33816047 | J9: =SUMIF(Data_Daily!$A$2:$A$2407,$A9,Data_Daily!$L$2:$L$2407) -> 28647997 | K9: =SUMIF(Data_Daily!$A$2:$A$2407,$A9,Data_Daily!$M$2:$M$2407) -> 28575884 | L9: =E9/D9 -> 0.65460062 | M9: =MIN(J9/I9,1) -> 0.84717166 | N9: =K9/J9 -> 0.99748279 | O9: =L9*M9*N9 -> 0.55316316 | P9: =(O9-Inputs!$B$5)*100 -> -9.6836844 | Q9: =E9/B9 -> 0.54677401
A10: Fleet | B10: =SUM(B5:B9) -> 44130.554 | C10: =SUM(C5:C9) -> 6534.1992 | D10: =SUM(D5:D9) -> 37596.355 | E10: =SUM(E5:E9) -> 24182.954 | F10: =SUM(F5:F9) -> 3147.4364 | G10: =SUM(G5:G9) -> 10265.964 | H10: =SUM(H5:H9) -> 4792.8325 | I10: =SUM(I5:I9) -> 1.1831757e+08 | ... K10: =SUM(K5:K9) -> 95166195 | L10: =E10/D10 -> 0.64322603 | M10: =MIN(J10/I10,1) -> 0.80763044 | N10: =K10/J10 -> 0.99591163 | O10: =L10*M10*N10 -> 0.51736506 | P10: =(O10-Inputs!$B$5)*100 -> -13.263494 | Q10: =E10/B10 -> 0.54798664

Sheet M3_LossTree
A1: M3 - Downtime / OEE loss tree (fleet)
A2: MEASURE. Parents are formulas; leaves come from M2 or v_loss_tree. Checks must read 0.
A4: Node | B4: Loss category | C4: Hours | D4: % of planned time | E4: Source
A5: 0 | B5: Logged time | C5: =M2_OEE!B10 -> 44130.554 | D5: =C5/$C$10 -> 1.1737987 | E5: M2
A6: 1 | B6: Scheduled downtime (planned, outside OEE) | C6: =M2_OEE!C10 -> 6534.1992 | D6: =C6/$C$10 -> 0.17379874 | E6: M2
A7: 1.1 | B7: Changeover / cleaning-like (10 min - 4 h) | C7: 5110.3056 | D7: =C7/$C$10 -> 0.13592556 | E7: v_loss_tree
A8: 1.2 | B8: Long shutdowns (> 4 h) | C8: 617.28883 | D8: =C8/$C$10 -> 0.016418848 | E8: v_loss_tree
A9: 1.3 | B9: Short planned stops (< 10 min) | C9: =C6-C7-C8 -> 806.60484 | D9: =C9/$C$10 -> 0.021454337 | E9: residual
A10: 2 | B10: Planned production time (PPT) | C10: =M2_OEE!D10 -> 37596.355 | D10: =C10/$C$10 -> 1 | E10: M2
A11: 2.1 | B11: Availability loss: alarm downtime | C11: =M2_OEE!F10 -> 3147.4364 | D11: =C11/$C$10 -> 0.083716532 | E11: M2
A12: 2.1.1 | B12: Alarm A_065 | C12: =M4_Pareto!C5 -> 857.92907 | D12: =C12/$C$10 -> 0.022819475 | E12: M4
A13: 2.1.2 | B13: Alarm A_101 | C13: =M4_Pareto!C6 -> 515.18852 | D13: =C13/$C$10 -> 0.013703151 | E13: M4
A14: 2.1.3 | B14: Alarm A_006 | C14: =M4_Pareto!C7 -> 411.22776 | D14: =C14/$C$10 -> 0.010937969 | E14: M4
A15: 2.1.4 | B15: Alarm A_001 | C15: =M4_Pareto!C8 -> 387.56895 | D15: =C15/$C$10 -> 0.010308684 | E15: M4
A16: 2.1.5 | B16: Alarm A_066 | C16: =M4_Pareto!C9 -> 153.42251 | D16: =C16/$C$10 -> 0.0040807815 | E16: M4
A17: 2.1.6 | B17: Other alarms | C17: =C11-SUM(C12:C16) -> 822.09961 | D17: =C17/$C$10 -> 0.021866471 | E17: residual
A18: 2.2 | B18: Availability loss: idle (no reason code) | C18: =M2_OEE!G10 -> 10265.964 | D18: =C18/$C$10 -> 0.27305744 | E18: M2
A19: 3 | B19: Run time | C19: =M2_OEE!E10 -> 24182.954 | D19: =C19/$C$10 -> 0.64322603 | E19: M2
A20: 3.1 | B20: Performance loss: reduced speed / minor stops | C20: 4463.6361 | D20: =C20/$C$10 -> 0.11872524 | E20: v_loss_tree
A21: 3.2 | B21: Performance loss: sub-rated running | C21: =C19-C22-C20 -> 188.42815 | D21: =C21/$C$10 -> 0.0050118729 | E21: residual
A22: 4 | B22: Net run time | C22: =C19*M2_OEE!M10 -> 19530.89 | D22: =C22/$C$10 -> 0.51948892 | E22: Run x P
A23: 4.1 | B23: Quality loss: rejects | C23: =C22-C24 -> 79.849538 | D23: =C23/$C$10 -> 0.0021238638 | E23: residual
A24: 5 | B24: Fully productive time (= OEE x PPT) | C24: =C22*M2_OEE!N10 -> 19451.04 | D24: =C24/$C$10 -> 0.51736506 | E24: Net x Q
B28: Check: PPT - (downtime + idle + run) = | C28: =C10-C11-C18-C19 -> 0
B29: Check: fully productive / PPT - OEE = | C29: =C24/C10-M2_OEE!O10 -> 0

Sheet M4_Pareto
A1: M4 - Pareto of alarm downtime (fleet)
A2: MEASURE. From v_pareto_alarm. Share, cumulative % and ABC class are formulas.
A4: Alarm | B4: Stops | C4: Downtime h | D4: MTTR min | E4: Machines | F4: Share | G4: Cumulative % | H4: Class | I4: Rank | K4: Vital few (class A codes) | L4: =COUNTIF(H5:H136,"A") -> 7
A5: A_065 | B5: 18864 | C5: 857.92907 | D5: 2.728782 | E5: 1 | F5: =C5/SUM($C$5:$C$136) -> 0.27258027 | G5: =SUM($C$5:C5)/SUM($C$5:$C$136) -> 0.27258027 | H5: =IF(G5-F5<0.8,"A",IF(G5-F5<0.95,"B","C")) -> A | I5: =RANK(C5,$C$5:$C$136) -> 1 | K5: Total alarm codes | L5: =COUNTA(A5:A136) -> 132
A6: A_101 | B6: 18399 | C6: 515.18852 | D6: 1.6800539 | E6: 3 | F6: =C6/SUM($C$5:$C$136) -> 0.16368512 | G6: =SUM($C$5:C6)/SUM($C$5:$C$136) -> 0.43626539 | H6: =IF(G6-F6<0.8,"A",IF(G6-F6<0.95,"B","C")) -> A | I6: =RANK(C6,$C$5:$C$136) -> 2 | K6: Class A share of downtime | L6: =SUMIF(H5:H136,"A",C5:C136)/SUM(C5:C136) -> 0.81591303
A7: A_006 | B7: 3922 | C7: 411.22776 | D7: 6.2910927 | E7: 4 | F7: =C7/SUM($C$5:$C$136) -> 0.13065483 | G7: =SUM($C$5:C7)/SUM($C$5:$C$136) -> 0.56692022 | H7: =IF(G7-F7<0.8,"A",IF(G7-F7<0.95,"B","C")) -> A | I7: =RANK(C7,$C$5:$C$136) -> 3
A8: A_001 | B8: 4401 | C8: 387.56895 | D8: 5.2838303 | E8: 4 | F8: =C8/SUM($C$5:$C$136) -> 0.12313798 | G8: =SUM($C$5:C8)/SUM($C$5:$C$136) -> 0.6900582 | H8: =IF(G8-F8<0.8,"A",IF(G8-F8<0.95,"B","C")) -> A | I8: =RANK(C8,$C$5:$C$136) -> 4
A9: A_066 | B9: 3375 | C9: 153.42251 | D9: 2.7275113 | E9: 2 | F9: =C9/SUM($C$5:$C$136) -> 0.048745229 | G9: =SUM($C$5:C9)/SUM($C$5:$C$136) -> 0.73880343 | H9: =IF(G9-F9<0.8,"A",IF(G9-F9<0.95,"B","C")) -> A | I9: =RANK(C9,$C$5:$C$136) -> 5
A10: A_005 | B10: 12225 | C10: 131.56096 | D10: 0.64569796 | E10: 5 | F10: =C10/SUM($C$5:$C$136) -> 0.041799402 | G10: =SUM($C$5:C10)/SUM($C$5:$C$136) -> 0.78060283 | H10: =IF(G10-F10<0.8,"A",IF(G10-F10<0.95,"B","C")) -> A | I10: =RANK(C10,$C$5:$C$136) -> 6
A11: A_020 | B11: 5098 | C11: 111.13663 | D11: 1.3080027 | E11: 5 | F11: =C11/SUM($C$5:$C$136) -> 0.035310206 | G11: =SUM($C$5:C11)/SUM($C$5:$C$136) -> 0.81591303 | H11: =IF(G11-F11<0.8,"A",IF(G11-F11<0.95,"B","C")) -> A | I11: =RANK(C11,$C$5:$C$136) -> 7
A12: A_010 | B12: 9275 | C12: 90.552497 | D12: 0.58578435 | E12: 5 | F12: =C12/SUM($C$5:$C$136) -> 0.028770239 | G12: =SUM($C$5:C12)/SUM($C$5:$C$136) -> 0.84468327 | H12: =IF(G12-F12<0.8,"A",IF(G12-F12<0.95,"B","C")) -> B | I12: =RANK(C12,$C$5:$C$136) -> 8
A13: A_016 | B13: 1142 | C13: 53.243437 | D13: 2.7973785 | E13: 5 | F13: =C13/SUM($C$5:$C$136) -> 0.016916445 | G13: =SUM($C$5:C13)/SUM($C$5:$C$136) -> 0.86159972 | H13: =IF(G13-F13<0.8,"A",IF(G13-F13<0.95,"B","C")) -> B | I13: =RANK(C13,$C$5:$C$136) -> 9
A14: A_003 | B14: 2225 | C14: 42.132123 | D14: 1.1361471 | E14: 5 | F14: =C14/SUM($C$5:$C$136) -> 0.013386171 | G14: =SUM($C$5:C14)/SUM($C$5:$C$136) -> 0.87498589 | H14: =IF(G14-F14<0.8,"A",IF(G14-F14<0.95,"B","C")) -> B | I14: =RANK(C14,$C$5:$C$136) -> 10
A15: A_067 | B15: 831 | C15: 40.946963 | D15: 2.9564594 | E15: 1 | F15: =C15/SUM($C$5:$C$136) -> 0.013009624 | G15: =SUM($C$5:C15)/SUM($C$5:$C$136) -> 0.88799551 | H15: =IF(G15-F15<0.8,"A",IF(G15-F15<0.95,"B","C")) -> B | I15: =RANK(C15,$C$5:$C$136) -> 11
A16: A_017 | B16: 1763 | C16: 37.191145 | D16: 1.2657225 | E16: 5 | F16: =C16/SUM($C$5:$C$136) -> 0.011816329 | G16: =SUM($C$5:C16)/SUM($C$5:$C$136) -> 0.89981184 | H16: =IF(G16-F16<0.8,"A",IF(G16-F16<0.95,"B","C")) -> B | I16: =RANK(C16,$C$5:$C$136) -> 12
A17: A_012 | B17: 1161 | C17: 36.3385 | D17: 1.8779587 | E17: 4 | F17: =C17/SUM($C$5:$C$136) -> 0.011545428 | G17: =SUM($C$5:C17)/SUM($C$5:$C$136) -> 0.91135727 | H17: =IF(G17-F17<0.8,"A",IF(G17-F17<0.95,"B","C")) -> B | I17: =RANK(C17,$C$5:$C$136) -> 13
A18: A_011 | B18: 1150 | C18: 36.107499 | D18: 1.8838695 | E18: 4 | F18: =C18/SUM($C$5:$C$136) -> 0.011472034 | G18: =SUM($C$5:C18)/SUM($C$5:$C$136) -> 0.9228293 | H18: =IF(G18-F18<0.8,"A",IF(G18-F18<0.95,"B","C")) -> B | I18: =RANK(C18,$C$5:$C$136) -> 14
... A136: A_107 | B136: 1 | C136: 0.0012972222 | D136: 0.077833333 | E136: 1 | F136: =C136/SUM($C$5:$C$136) -> 4.12152e-07 | G136: =SUM($C$5:C136)/SUM($C$5:$C$136) -> 1 | H136: =IF(G136-F136<0.8,"A",IF(G136-F136<0.95,"B","C")) -> C | I136: =RANK(C136,$C$5:$C$136) -> 132

Sheet M5_Reliability
A1: M5 - Reliability: MTBF / MTTR
A2: MEASURE. Stops/downtime from v_reliability; run hours linked from M2.
A4: Machine | B4: Alarm stops | C4: Downtime h | D4: Run h | E4: MTBF (run-min) | F4: MTTR (min) | G4: Inherent availability | H4: Stops per run-hour
A5: s_1 | B5: 32576 | C5: 1393.3596 | D5: =M2_OEE!E5 -> 9245.5438 | E5: =D5/B5*60 -> 17.028875 | F5: =C5/B5*60 -> 2.5663549 | G5: =E5/(E5+F5) -> 0.86903165 | H5: =B5/D5 -> 3.5234272
A6: s_2 | B6: 17361 | C6: 573.78872 | D6: =M2_OEE!E6 -> 1719.7614 | E6: =D6/B6*60 -> 5.9435335 | F6: =C6/B6*60 -> 1.9830265 | G6: =E6/(E6+F6) -> 0.74982508 | H6: =B6/D6 -> 10.095005
A7: s_3 | B7: 7777 | C7: 466.29693 | D7: =M2_OEE!E7 -> 3326.6326 | E7: =D7/B7*60 -> 25.665161 | F7: =C7/B7*60 -> 3.5975075 | G7: =E7/(E7+F7) -> 0.87706153 | H7: =B7/D7 -> 2.3377995
A8: s_4 | B8: 18250 | C8: 358.38358 | D8: =M2_OEE!E8 -> 4238.2206 | E8: =D8/B8*60 -> 13.933876 | F8: =C8/B8*60 -> 1.1782474 | G8: =E8/(E8+F8) -> 0.92203297 | H8: =B8/D8 -> 4.3060525
A9: s_5 | B9: 16041 | C9: 355.60755 | D9: =M2_OEE!E9 -> 5652.7956 | E9: =D9/B9*60 -> 21.143802 | F9: =C9/B9*60 -> 1.3301199 | G9: =E9/(E9+F9) -> 0.94081496 | H9: =B9/D9 -> 2.837711
A10: Fleet | B10: =SUM(B5:B9) -> 92005 | C10: =SUM(C5:C9) -> 3147.4364 | D10: =SUM(D5:D9) -> 24182.954 | E10: =D10/B10*60 -> 15.770635 | F10: =C10/B10*60 -> 2.0525644 | G10: =E10/(E10+F10) -> 0.88483749 | H10: =B10/D10 -> 3.8045394
A12: Reading: MTTR of 1-4 min and MTBF of 6-26 run-minutes = MINOR STOPS, not breakdowns. That points to Kaizen, autonomous maintenance and Poka-Yoke rather than spare parts or big repairs.

Sheet M6_Sigma
A1: M6 - Six Sigma baseline: DPMO and sigma level
A2: MEASURE. Sigma (short-term) = NORMSINV(yield) + 1.5 shift.
A4: Scope | B4: Opportunities (units in) | C4: Defects | D4: DPMO | E4: Yield | F4: Sigma level (ST)
A5: s_1 - package rejects | B5: =M2_OEE!J5 -> 31286632 | C5: =M2_OEE!J5-M2_OEE!K5 -> 138581 | D5: =C5/B5*1000000 -> 4429.3998 | E5: =1-C5/B5 -> 0.9955706 | F5: =NORMSINV(E5)+1.5 -> 4.1174557
A6: s_2 - package rejects | B6: =M2_OEE!J6 -> 8337448 | C6: =M2_OEE!J6-M2_OEE!K6 -> 44585 | D6: =C6/B6*1000000 -> 5347.5596 | E6: =1-C6/B6 -> 0.99465244 | F6: =NORMSINV(E6)+1.5 -> 4.0525056
A7: s_3 - package rejects | B7: =M2_OEE!J7 -> 11927022 | C7: =M2_OEE!J7-M2_OEE!K7 -> 28508 | D7: =C7/B7*1000000 -> 2390.2027 | E7: =1-C7/B7 -> 0.9976098 | F7: =NORMSINV(E7)+1.5 -> 4.3214704
A8: s_4 - package rejects | B8: =M2_OEE!J8 -> 15357768 | C8: =M2_OEE!J8-M2_OEE!K8 -> 106885 | D8: =C8/B8*1000000 -> 6959.6702 | E8: =1-C8/B8 -> 0.99304033 | F8: =NORMSINV(E8)+1.5 -> 3.9593383
A9: s_5 - package rejects | B9: =M2_OEE!J9 -> 28647997 | C9: =M2_OEE!J9-M2_OEE!K9 -> 72113 | D9: =C9/B9*1000000 -> 2517.2091 | E9: =1-C9/B9 -> 0.99748279 | F9: =NORMSINV(E9)+1.5 -> 4.3048232
A10: Fleet - package rejects | B10: =M2_OEE!J10 -> 95556867 | C10: =M2_OEE!J10-M2_OEE!K10 -> 390672 | D10: =C10/B10*1000000 -> 4088.3718 | E10: =1-C10/B10 -> 0.99591163 | F10: =NORMSINV(E10)+1.5 -> 4.1446832
A11: s_1 - days below OEE target (X-bar subgroups) | B11: =COUNT(C1_XbarR_s1!F16:F2000) -> 479 | C11: =COUNTIF(C1_XbarR_s1!F16:F2000,"<"&Inputs!B5) -> 221 | D11: =C11/B11*1000000 -> 461377.87 | E11: =1-C11/B11 -> 0.53862213 | F11: =NORMSINV(E11)+1.5 -> 1.596963
A13: Reading: package quality is already ~4 sigma, so quality is NOT the problem. Measured against the OEE target, s_1 is only a ~1.6-sigma process: time loss, not defects, is the defect that matters.

Sheet A1_RCA
A1: A1 - Root cause analysis: Fishbone (6M) + 5 Whys
A2: ANALYZE. [data] = verified in PIADE; [hyp.] = must be verified at the gemba before acting.
A4: 6M category | B4: Potential cause | C4: Evidence | D4: Status
A5: Machine | B5: A_065 micro-stops on s_1 | C5: 858 h, 18,864 stops, MTTR 2.7 min (M4) | D5: [data]
A6: Machine | B6: A_101 repeat stops on s_2/s_3/s_5 | C6: 515 h; 70% recur within 30 min (A2) | D6: [data]
A7: Machine | B7: A_001 / A_006 long stops | C7: MTTR 5-6 min, highest RPN (A2) | D7: [data]
A8: Machine | B8: Reduced-speed running on s_4 | C8: 21% of s_4 logged time in performance_loss state | D8: [data]
A9: Method | B9: Changeovers not standardised | C9: Mean 37-68 min, P90 up to 167 min (I3) | D9: [data]
A10: Method | B10: Start-of-day restarts | C10: Shift A alarm-downtime share highest (A3) | D10: [data]
A11: Measurement | B11: Idle has no reason code | C11: 27% of PPT unexplained (M1, M3) | D11: [data]
A12: Measurement | B12: Alarm codes anonymised, no hierarchy | C12: 132 codes, no family / component map | D12: [data]
A13: People | B13: Night and weekend under-staffing | C13: Idle share C shift and weekends significantly higher (A3) | D13: [data]
A14: People | B14: Recovery skill varies by operator | C14: Not in data - verify with MTTR by crew | D14: [hyp.]
A15: Material | B15: Line starvation behind idle | C15: Not coded - verify with reason codes | D15: [hyp.]
... A17: Environment | B17: s_1 degraded in 2021 | C17: s_1 OEE 67.8% -> 62.7%; all other machines improved (A3) | D17: [data]
A19: 5 Whys - A_065 on s_1
A20: Why? | B20: Answer | C20: Evidence / status
A21: 1. Why is s_1 OEE below target? | B21: Availability loss from frequent alarm stops | C21: A_065 = 62% of s_1 alarm downtime [data]
A22: 2. Why so much A_065 downtime? | B22: Very frequent short stops (~2 per run-hour), not long ones | C22: Median 1.3 min, 18.9k events [data]
A23: 3. Why so frequent? | B23: Stops cluster: 81% recur within 30 min of the previous one | C23: Repeat rate [data]
A24: 4. Why do they recur? | B24: Operator clears the jam but the trigger condition is not removed | C24: [hyp.] - observe 20 stops at the gemba
A25: 5. Why is the trigger not removed? | B25: No standard for root-cause fixing of micro-stops; no CIL routine | C25: [hyp.] -> Kaizen + CIL + Poka-Yoke
A27: 5 Whys - Idle time
A28: Why? | B28: Answer | C28: Evidence / status
A29: 1. Why is availability only 64%? | B29: 27% of planned time is idle | C29: M3 [data]
A30: 2. Why is the machine idle? | B30: Unknown - idle rows carry no reason code | C30: M1 [data]
A31: 3. When is it idle? | B31: Night shift (C) and weekends | C31: A3 ANOVA / t-test [data]
A32: 4. Why then? | B32: Likely thin staffing / no material staged / no orders | C32: [hyp.]
A33: 5. Why can't we tell? | B33: The data system never asks the operator why | C33: Root cause = measurement gap -> Poka-Yoke on data entry

Sheet A2_FMEA
A1: A2 - Data-driven FMEA (top 10 failure modes by downtime)
A2: ANALYZE. S from MTTR, O from stops per 1,000 run-hours, D from 'repeat within 30 min' (a failure that recurs announces itself -> easier to detect). Scales at right.
A4: Failure mode | B4: Machines | C4: Effect | D4: Stops | E4: Downtime h | F4: MTTR min | G4: Stops / 1000 run-h | H4: Repeat <= 30 min | I4: S | J4: O | K4: D | L4: RPN | M4: Priority | N4: Recommended action | Q4: MTTR >= (min) | R4: S | T4: Stops/1000h >= | U4: O
A5: A_065 | B5: s_1 | C5: Machine stop, lost output | D5: 18864 | E5: 857.92907 | F5: 2.728782 | G5: 2040.3343 | H5: 0.80550254 | I5: =LOOKUP(F5,$Q$5:$Q$14,$R$5:$R$14) -> 4 | J5: =LOOKUP(G5,$T$5:$T$14,$U$5:$U$14) -> 8 | K5: =MAX(2,MIN(10,ROUND(10-8*H5,0))) -> 4 | L5: =I5*J5*K5 -> 128 | M5: =IF(L5>=200,"High",IF(L5>=120,"Medium","Low")) -> Medium | N5: =IF(I5>=6,"Poka-Yoke + standard repair kit (long stops)",IF(J5>=8,"Kaizen blitz: high-frequency micro-stop","5S / visual control + monitor")) -> Kaizen blitz: high-frequency micro-stop | Q5: 0 | R5: 1 | T5: 0 | U5: 1
A6: A_101 | B6: s_2, s_3, s_5 | C6: Machine stop, lost output | D6: 18399 | E6: 515.18852 | F6: 1.6800539 | G6: 1719.663 | H6: 0.70253818 | I6: =LOOKUP(F6,$Q$5:$Q$14,$R$5:$R$14) -> 3 | J6: =LOOKUP(G6,$T$5:$T$14,$U$5:$U$14) -> 8 | K6: =MAX(2,MIN(10,ROUND(10-8*H6,0))) -> 4 | L6: =I6*J6*K6 -> 96 | M6: =IF(L6>=200,"High",IF(L6>=120,"Medium","Low")) -> Low | N6: =IF(I6>=6,"Poka-Yoke + standard repair kit (long stops)",IF(J6>=8,"Kaizen blitz: high-frequency micro-stop","5S / visual control + monitor")) -> Kaizen blitz: high-frequency micro-stop | Q6: 0.5 | R6: 2 | T6: 1 | U6: 2
A7: A_006 | B7: s_1, s_2, s_3, s_4 | C7: Machine stop, lost output | D7: 3922 | E7: 411.22776 | F7: 6.2910927 | G7: 211.65496 | H7: 0.2763896 | I7: =LOOKUP(F7,$Q$5:$Q$14,$R$5:$R$14) -> 6 | J7: =LOOKUP(G7,$T$5:$T$14,$U$5:$U$14) -> 6 | K7: =MAX(2,MIN(10,ROUND(10-8*H7,0))) -> 8 | L7: =I7*J7*K7 -> 288 | M7: =IF(L7>=200,"High",IF(L7>=120,"Medium","Low")) -> High | N7: =IF(I7>=6,"Poka-Yoke + standard repair kit (long stops)",IF(J7>=8,"Kaizen blitz: high-frequency micro-stop","5S / visual control + monitor")) -> Poka-Yoke + standard repair kit (long stops) | Q7: 1 | R7: 3 | T7: 3 | U7: 3
A8: A_001 | B8: s_1, s_2, s_3, s_4 | C8: Machine stop, lost output | D8: 4401 | E8: 387.56895 | F8: 5.2838303 | G8: 237.50472 | H8: 0.14928425 | I8: =LOOKUP(F8,$Q$5:$Q$14,$R$5:$R$14) -> 6 | J8: =LOOKUP(G8,$T$5:$T$14,$U$5:$U$14) -> 6 | K8: =MAX(2,MIN(10,ROUND(10-8*H8,0))) -> 9 | L8: =I8*J8*K8 -> 324 | M8: =IF(L8>=200,"High",IF(L8>=120,"Medium","Low")) -> High | N8: =IF(I8>=6,"Poka-Yoke + standard repair kit (long stops)",IF(J8>=8,"Kaizen blitz: high-frequency micro-stop","5S / visual control + monitor")) -> Poka-Yoke + standard repair kit (long stops) | Q8: 2 | R8: 4 | T8: 10 | U8: 4
A9: A_066 | B9: s_1, s_5 | C9: Machine stop, lost output | D9: 3375 | E9: 153.42251 | F9: 2.7275113 | G9: 226.53532 | H9: 0.6717037 | I9: =LOOKUP(F9,$Q$5:$Q$14,$R$5:$R$14) -> 4 | J9: =LOOKUP(G9,$T$5:$T$14,$U$5:$U$14) -> 6 | K9: =MAX(2,MIN(10,ROUND(10-8*H9,0))) -> 5 | L9: =I9*J9*K9 -> 120 | M9: =IF(L9>=200,"High",IF(L9>=120,"Medium","Low")) -> Medium | N9: =IF(I9>=6,"Poka-Yoke + standard repair kit (long stops)",IF(J9>=8,"Kaizen blitz: high-frequency micro-stop","5S / visual control + monitor")) -> 5S / visual control + monitor | Q9: 3 | R9: 5 | T9: 30 | U9: 5
A10: A_005 | B10: s_1, s_2, s_3, s_4, s_5 | C10: Machine stop, lost output | D10: 12225 | E10: 131.56096 | F10: 0.64569796 | G10: 505.52137 | H10: 0.69063395 | I10: =LOOKUP(F10,$Q$5:$Q$14,$R$5:$R$14) -> 2 | J10: =LOOKUP(G10,$T$5:$T$14,$U$5:$U$14) -> 7 | K10: =MAX(2,MIN(10,ROUND(10-8*H10,0))) -> 4 | L10: =I10*J10*K10 -> 56 | M10: =IF(L10>=200,"High",IF(L10>=120,"Medium","Low")) -> Low | N10: =IF(I10>=6,"Poka-Yoke + standard repair kit (long stops)",IF(J10>=8,"Kaizen blitz: high-frequency micro-stop","5S / visual control + monitor")) -> 5S / visual control + monitor | Q10: 5 | R10: 6 | T10: 100 | U10: 6
A11: A_020 | B11: s_1, s_2, s_3, s_4, s_5 | C11: Machine stop, lost output | D11: 5098 | E11: 111.13663 | F11: 1.3080027 | G11: 210.80965 | H11: 0.51824245 | I11: =LOOKUP(F11,$Q$5:$Q$14,$R$5:$R$14) -> 3 | J11: =LOOKUP(G11,$T$5:$T$14,$U$5:$U$14) -> 6 | K11: =MAX(2,MIN(10,ROUND(10-8*H11,0))) -> 6 | L11: =I11*J11*K11 -> 108 | M11: =IF(L11>=200,"High",IF(L11>=120,"Medium","Low")) -> Low | N11: =IF(I11>=6,"Poka-Yoke + standard repair kit (long stops)",IF(J11>=8,"Kaizen blitz: high-frequency micro-stop","5S / visual control + monitor")) -> 5S / visual control + monitor | Q11: 10 | R11: 7 | T11: 300 | U11: 7
A12: A_010 | B12: s_1, s_2, s_3, s_4, s_5 | C12: Machine stop, lost output | D12: 9275 | E12: 90.552497 | F12: 0.58578435 | G12: 383.53462 | H12: 0.61455526 | I12: =LOOKUP(F12,$Q$5:$Q$14,$R$5:$R$14) -> 2 | J12: =LOOKUP(G12,$T$5:$T$14,$U$5:$U$14) -> 7 | K12: =MAX(2,MIN(10,ROUND(10-8*H12,0))) -> 5 | L12: =I12*J12*K12 -> 70 | M12: =IF(L12>=200,"High",IF(L12>=120,"Medium","Low")) -> Low | N12: =IF(I12>=6,"Poka-Yoke + standard repair kit (long stops)",IF(J12>=8,"Kaizen blitz: high-frequency micro-stop","5S / visual control + monitor")) -> 5S / visual control + monitor | Q12: 20 | R12: 8 | T12: 1000 | U12: 8
A13: A_016 | B13: s_1, s_2, s_3, s_4, s_5 | C13: Machine stop, lost output | D13: 1142 | E13: 53.243437 | F13: 2.7973785 | G13: 47.223346 | H13: 0.1357268 | I13: =LOOKUP(F13,$Q$5:$Q$14,$R$5:$R$14) -> 4 | J13: =LOOKUP(G13,$T$5:$T$14,$U$5:$U$14) -> 5 | K13: =MAX(2,MIN(10,ROUND(10-8*H13,0))) -> 9 | L13: =I13*J13*K13 -> 180 | M13: =IF(L13>=200,"High",IF(L13>=120,"Medium","Low")) -> Medium | N13: =IF(I13>=6,"Poka-Yoke + standard repair kit (long stops)",IF(J13>=8,"Kaizen blitz: high-frequency micro-stop","5S / visual control + monitor")) -> 5S / visual control + monitor | Q13: 60 | R13: 9 | T13: 3000 | U13: 9
A14: A_003 | B14: s_1, s_2, s_3, s_4, s_5 | C14: Machine stop, lost output | D14: 2225 | E14: 42.132123 | F14: 1.1361471 | G14: 92.006957 | H14: 0.54741573 | I14: =LOOKUP(F14,$Q$5:$Q$14,$R$5:$R$14) -> 3 | J14: =LOOKUP(G14,$T$5:$T$14,$U$5:$U$14) -> 5 | K14: =MAX(2,MIN(10,ROUND(10-8*H14,0))) -> 6 | L14: =I14*J14*K14 -> 90 | M14: =IF(L14>=200,"High",IF(L14>=120,"Medium","Low")) -> Low | N14: =IF(I14>=6,"Poka-Yoke + standard repair kit (long stops)",IF(J14>=8,"Kaizen blitz: high-frequency micro-stop","5S / visual control + monitor")) -> 5S / visual control + monitor | Q14: 120 | R14: 10 | T14: 10000 | U14: 10
A16: Reading: Pareto ranks by impact (A_065 first); FMEA ranks by risk (A_001 / A_006 first - long, unpredictable stops). Use both: Kaizen for the frequent ones, Poka-Yoke for the risky ones.

Sheet A3_Hypothesis
A1: A3 - Hypothesis tests (Excel-native formulas, alpha = 0.05)
A2: ANALYZE. Data_Shift = v_shift_state_share (machine x day x shift, planned >= 1 h); Data_Daily = v_daily_machine. Large n makes ANOVA / Welch robust to non-normality.
A4: H1: Mean IDLE share is equal across shifts A, B, C (one-way ANOVA) | F4: H2: Mean ALARM-DOWNTIME share is equal across shifts (one-way ANOVA)
A5: Shift | B5: n | C5: Mean idle share | D5: SS within | F5: Shift | G5: n | H5: Mean downtime share | I5: SS within
A6: A | B6: =COUNTIF(Data_Shift!$C$2:$C$5993,A6) -> 2177 | C6: =AVERAGEIF(Data_Shift!$C$2:$C$5993,A6,Data_Shift!$D$2:$D$5993) -> 0.27023631 | D6: =SUMPRODUCT((Data_Shift!$C$2:$C$5993=A6)*(Data_Shift!$D$2:$D$5993-C6)^2) -> 186.85844 | F6: A | G6: =COUNTIF(Data_Shift!$C$2:$C$5993,F6) -> 2177 | H6: =AVERAGEIF(Data_Shift!$C$2:$C$5993,F6,Data_Shift!$E$2:$E$5993) -> 0.097862605 | I6: =SUMPRODUCT((Data_Shift!$C$2:$C$5993=F6)*(Data_Shift!$E$2:$E$5993-H6)^2) -> 18.850037
A7: B | B7: =COUNTIF(Data_Shift!$C$2:$C$5993,A7) -> 1741 | C7: =AVERAGEIF(Data_Shift!$C$2:$C$5993,A7,Data_Shift!$D$2:$D$5993) -> 0.19432885 | D7: =SUMPRODUCT((Data_Shift!$C$2:$C$5993=A7)*(Data_Shift!$D$2:$D$5993-C7)^2) -> 131.54663 | F7: B | G7: =COUNTIF(Data_Shift!$C$2:$C$5993,F7) -> 1741 | H7: =AVERAGEIF(Data_Shift!$C$2:$C$5993,F7,Data_Shift!$E$2:$E$5993) -> 0.075882718 | I7: =SUMPRODUCT((Data_Shift!$C$2:$C$5993=F7)*(Data_Shift!$E$2:$E$5993-H7)^2) -> 10.954488
A8: C | B8: =COUNTIF(Data_Shift!$C$2:$C$5993,A8) -> 2074 | C8: =AVERAGEIF(Data_Shift!$C$2:$C$5993,A8,Data_Shift!$D$2:$D$5993) -> 0.38522322 | D8: =SUMPRODUCT((Data_Shift!$C$2:$C$5993=A8)*(Data_Shift!$D$2:$D$5993-C8)^2) -> 316.60335 | F8: C | G8: =COUNTIF(Data_Shift!$C$2:$C$5993,F8) -> 2074 | H8: =AVERAGEIF(Data_Shift!$C$2:$C$5993,F8,Data_Shift!$E$2:$E$5993) -> 0.074793263 | I8: =SUMPRODUCT((Data_Shift!$C$2:$C$5993=F8)*(Data_Shift!$E$2:$E$5993-H8)^2) -> 22.135329
A9: Grand mean | B9: =SUMPRODUCT(B6:B8,C6:C8)/SUM(B6:B8) -> 0.2879813 | F9: Grand mean | G9: =SUMPRODUCT(G6:G8,H6:H8)/SUM(G6:G8) -> 0.08349131
A10: SS between | B10: =SUMPRODUCT(B6:B8,(C6:C8-B9)^2) -> 35.567159 | F10: SS between | G10: =SUMPRODUCT(G6:G8,(H6:H8-G9)^2) -> 0.70732298
A11: SS within | B11: =SUM(D6:D8) -> 635.00843 | F11: SS within | G11: =SUM(I6:I8) -> 51.939853
A12: df between / within | B12: =2 -> 2 | F12: df between | G12: =2 -> 2
B13: =SUM(B6:B8)-3 -> 5989 | F13: df within | G13: =SUM(G6:G8)-3 -> 5989
A14: F statistic | B14: =(B10/B12)/(B11/B13) -> 167.72353 | F14: F statistic | G14: =(G10/G12)/(G11/G13) -> 40.77945
A15: p-value | B15: =FDIST(B14,B12,B13) -> 1.334838e-71 | F15: p-value | G15: =FDIST(G14,G12,G13) -> 2.5657619e-18
A16: Decision | B16: =IF(B15<0.05,"Reject H0: idle differs by shift","Fail to reject H0") -> Reject H0: idle differs by shift | F16: Decision | G16: =IF(G15<0.05,"Reject H0: downtime differs by shift","Fail to reject H0") -> Reject H0: downtime differs by shift
A19: H3: Weekend idle share <= weekday idle share (Welch two-sample t, one-tailed) | F19: H4: Top-alarm mix is independent of shift (chi-square test of independence)
A20: Group | B20: n | C20: Mean | D20: Variance | F20: Alarm group | G20: Shift A | H20: Shift B | I20: Shift C | J20: Row total
A21: Weekend | B21: =COUNTIF(Data_Shift!$F$2:$F$5993,1) -> 1362 | C21: =AVERAGEIF(Data_Shift!$F$2:$F$5993,1,Data_Shift!$D$2:$D$5993) -> 0.35944137 | D21: =SUMPRODUCT((Data_Shift!$F$2:$F$5993=1)*(Data_Shift!$D$2:$D$5993-C21)^2)/(B21-1) -> 0.13890488 | F21: A_001 | G21: 2718 | H21: 616 | I21: 1067 | J21: =SUM(G21:I21) -> 4401
A22: Weekday | B22: =COUNTIF(Data_Shift!$F$2:$F$5993,0) -> 4630 | C22: =AVERAGEIF(Data_Shift!$F$2:$F$5993,0,Data_Shift!$D$2:$D$5993) -> 0.26696 | D22: =SUMPRODUCT((Data_Shift!$F$2:$F$5993=0)*(Data_Shift!$D$2:$D$5993-C22)^2)/(B22-1) -> 0.10207927 | F22: A_006 | G22: 1746 | H22: 1153 | I22: 1023 | J22: =SUM(G22:I22) -> 3922
A23: t statistic | B23: =(C21-C22)/SQRT(D21/B21+D22/B22) -> 8.303957 | F23: A_065 | G23: 10551 | H23: 3748 | I23: 4565 | J23: =SUM(G23:I23) -> 18864
A24: Welch df | B24: =(D21/B21+D22/B22)^2/((D21/B21)^2/(B21-1)+(D22/B22)^2/(B22-1)) -> 1985.7623 | F24: A_101 | G24: 9363 | H24: 4259 | I24: 4777 | J24: =SUM(G24:I24) -> 18399
A25: p-value (one-tailed) | B25: =TDIST(ABS(B23),B24,1) -> 9.195471e-17 | F25: other | G25: 13460 | H25: 17656 | I25: 15303 | J25: =SUM(G25:I25) -> 46419
A26: Decision | B26: =IF(AND(B25<0.05,B23>0),"Reject H0: weekends idle more","Fail to reject H0") -> Reject H0: weekends idle more | F26: Column total | G26: =SUM(G21:G25) -> 37838 | H26: =SUM(H21:H25) -> 27432 | I26: =SUM(I21:I25) -> 26735 | J26: =SUM(J21:J25) -> 92005
F28: Expected | G28: Shift A | H28: Shift B | I28: Shift C
F29: =F21 -> A_001 | G29: =$J21*G$26/$J$26 -> 1809.9564 | H29: =$J21*H$26/$J$26 -> 1312.1921 | I29: =$J21*I$26/$J$26 -> 1278.8515
F30: =F22 -> A_006 | G30: =$J22*G$26/$J$26 -> 1612.9627 | H30: =$J22*H$26/$J$26 -> 1169.3745 | I30: =$J22*I$26/$J$26 -> 1139.6627
F31: =F23 -> A_065 | G31: =$J23*G$26/$J$26 -> 7758.0135 | H31: =$J23*H$26/$J$26 -> 5624.447 | I31: =$J23*I$26/$J$26 -> 5481.5395
F32: =F24 -> A_101 | G32: =$J24*G$26/$J$26 -> 7566.7775 | H32: =$J24*H$26/$J$26 -> 5485.8037 | I32: =$J24*I$26/$J$26 -> 5346.4188
F33: =F25 -> other | G33: =$J25*G$26/$J$26 -> 19090.29 | H33: =$J25*H$26/$J$26 -> 13840.183 | I33: =$J25*I$26/$J$26 -> 13488.527
F34: Chi-square | G34: =SUMPRODUCT((G21:I25-G29:I33)^2/G29:I33) -> 6386.0111
F35: p-value | G35: =CHITEST(G21:I25,G29:I33) -> 0
F36: Cramer's V (effect size) | G36: =SQRT(G34/(J26*2)) -> 0.18629196
F37: Decision | G37: =IF(G35<0.05,"Reject H0 (but check effect size)","Fail to reject H0") -> Reject H0 (but check effect size)
A39: H5: Daily OEE is equal in 2020 and 2021 - tested PER MACHINE (Welch t, two-tailed). Stratify first: the pooled fleet 'decline' is a mix effect.
A40: Machine | B40: n 2020 | C40: Mean 2020 | D40: Var 2020 | E40: n 2021 | F40: Mean 2021 | G40: Var 2021 | H40: Change (pts) | I40: t | J40: df | K40: p-value | L40: Decision
A41: s_1 | B41: =COUNTIFS(Data_Daily!$A$2:$A$2407,$A41,Data_Daily!$O$2:$O$2407,2020,Data_Daily!$P$2:$P$2407,1) -> 323 | C41: =AVERAGEIFS(Data_Daily!$Q$2:$Q$2407,Data_Daily!$A$2:$A$2407,$A41,Data_Daily!$O$2:$O$2407,2020,Data_Daily!$P$2:$P$2407,1) -> 0.66657556 | D41: =SUMPRODUCT((Data_Daily!$A$2:$A$2407=$A41)*(Data_Daily!$O$2:$O$2407=2020)*(Data_Daily!$P$2:$P$2407=1)*(Data_Daily!$Q$2:$Q$2407-C41)^2)/(B41-1) -> 0.021354208 | E41: =COUNTIFS(Data_Daily!$A$2:$A$2407,$A41,Data_Daily!$O$2:$O$2407,2021,Data_Daily!$P$2:$P$2407,1) -> 298 | F41: =AVERAGEIFS(Data_Daily!$Q$2:$Q$2407,Data_Daily!$A$2:$A$2407,$A41,Data_Daily!$O$2:$O$2407,2021,Data_Daily!$P$2:$P$2407,1) -> 0.62180236 | G41: =SUMPRODUCT((Data_Daily!$A$2:$A$2407=$A41)*(Data_Daily!$O$2:$O$2407=2021)*(Data_Daily!$P$2:$P$2407=1)*(Data_Daily!$Q$2:$Q$2407-F41)^2)/(E41-1) -> 0.015927034 | H41: =(F41-C41)*100 -> -4.4773207 | I41: =(F41-C41)/SQRT(D41/B41+G41/E41) -> -4.0947551 | J41: =(D41/B41+G41/E41)^2/((D41/B41)^2/(B41-1)+(G41/E41)^2/(E41-1)) -> 616.3474 | K41: =TDIST(ABS(I41),J41,2) -> 4.7899201e-05 | L41: =IF(K41<0.05,IF(H41<0,"Significant DROP","Significant RISE"),"No change") -> Significant DROP
A42: s_2 | B42: =COUNTIFS(Data_Daily!$A$2:$A$2407,$A42,Data_Daily!$O$2:$O$2407,2020,Data_Daily!$P$2:$P$2407,1) -> 106 | C42: =AVERAGEIFS(Data_Daily!$Q$2:$Q$2407,Data_Daily!$A$2:$A$2407,$A42,Data_Daily!$O$2:$O$2407,2020,Data_Daily!$P$2:$P$2407,1) -> 0.26155741 | D42: =SUMPRODUCT((Data_Daily!$A$2:$A$2407=$A42)*(Data_Daily!$O$2:$O$2407=2020)*(Data_Daily!$P$2:$P$2407=1)*(Data_Daily!$Q$2:$Q$2407-C42)^2)/(B42-1) -> 0.016718646 | E42: =COUNTIFS(Data_Daily!$A$2:$A$2407,$A42,Data_Daily!$O$2:$O$2407,2021,Data_Daily!$P$2:$P$2407,1) -> 313 | F42: =AVERAGEIFS(Data_Daily!$Q$2:$Q$2407,Data_Daily!$A$2:$A$2407,$A42,Data_Daily!$O$2:$O$2407,2021,Data_Daily!$P$2:$P$2407,1) -> 0.35640397 | G42: =SUMPRODUCT((Data_Daily!$A$2:$A$2407=$A42)*(Data_Daily!$O$2:$O$2407=2021)*(Data_Daily!$P$2:$P$2407=1)*(Data_Daily!$Q$2:$Q$2407-F42)^2)/(E42-1) -> 0.014287451 | H42: =(F42-C42)*100 -> 9.4846554 | I42: =(F42-C42)/SQRT(D42/B42+G42/E42) -> 6.6508665 | J42: =(D42/B42+G42/E42)^2/((D42/B42)^2/(B42-1)+(G42/E42)^2/(E42-1)) -> 169.78509 | K42: =TDIST(ABS(I42),J42,2) -> 3.8702351e-10 | L42: =IF(K42<0.05,IF(H42<0,"Significant DROP","Significant RISE"),"No change") -> Significant RISE
A43: s_3 | B43: =COUNTIFS(Data_Daily!$A$2:$A$2407,$A43,Data_Daily!$O$2:$O$2407,2020,Data_Daily!$P$2:$P$2407,1) -> 68 | C43: =AVERAGEIFS(Data_Daily!$Q$2:$Q$2407,Data_Daily!$A$2:$A$2407,$A43,Data_Daily!$O$2:$O$2407,2020,Data_Daily!$P$2:$P$2407,1) -> 0.38487705 | D43: =SUMPRODUCT((Data_Daily!$A$2:$A$2407=$A43)*(Data_Daily!$O$2:$O$2407=2020)*(Data_Daily!$P$2:$P$2407=1)*(Data_Daily!$Q$2:$Q$2407-C43)^2)/(B43-1) -> 0.012588546 | E43: =COUNTIFS(Data_Daily!$A$2:$A$2407,$A43,Data_Daily!$O$2:$O$2407,2021,Data_Daily!$P$2:$P$2407,1) -> 286 | F43: =AVERAGEIFS(Data_Daily!$Q$2:$Q$2407,Data_Daily!$A$2:$A$2407,$A43,Data_Daily!$O$2:$O$2407,2021,Data_Daily!$P$2:$P$2407,1) -> 0.46682651 | G43: =SUMPRODUCT((Data_Daily!$A$2:$A$2407=$A43)*(Data_Daily!$O$2:$O$2407=2021)*(Data_Daily!$P$2:$P$2407=1)*(Data_Daily!$Q$2:$Q$2407-F43)^2)/(E43-1) -> 0.010100839 | H43: =(F43-C43)*100 -> 8.1949459 | I43: =(F43-C43)/SQRT(D43/B43+G43/E43) -> 5.5194733 | J43: =(D43/B43+G43/E43)^2/((D43/B43)^2/(B43-1)+(G43/E43)^2/(E43-1)) -> 94.196589 | K43: =TDIST(ABS(I43),J43,2) -> 2.9970978e-07 | L43: =IF(K43<0.05,IF(H43<0,"Significant DROP","Significant RISE"),"No change") -> Significant RISE
A44: s_4 | B44: =COUNTIFS(Data_Daily!$A$2:$A$2407,$A44,Data_Daily!$O$2:$O$2407,2020,Data_Daily!$P$2:$P$2407,1) -> 89 | C44: =AVERAGEIFS(Data_Daily!$Q$2:$Q$2407,Data_Daily!$A$2:$A$2407,$A44,Data_Daily!$O$2:$O$2407,2020,Data_Daily!$P$2:$P$2407,1) -> 0.44252689 | D44: =SUMPRODUCT((Data_Daily!$A$2:$A$2407=$A44)*(Data_Daily!$O$2:$O$2407=2020)*(Data_Daily!$P$2:$P$2407=1)*(Data_Daily!$Q$2:$Q$2407-C44)^2)/(B44-1) -> 0.015464749 | E44: =COUNTIFS(Data_Daily!$A$2:$A$2407,$A44,Data_Daily!$O$2:$O$2407,2021,Data_Daily!$P$2:$P$2407,1) -> 235 | F44: =AVERAGEIFS(Data_Daily!$Q$2:$Q$2407,Data_Daily!$A$2:$A$2407,$A44,Data_Daily!$O$2:$O$2407,2021,Data_Daily!$P$2:$P$2407,1) -> 0.48218518 | G44: =SUMPRODUCT((Data_Daily!$A$2:$A$2407=$A44)*(Data_Daily!$O$2:$O$2407=2021)*(Data_Daily!$P$2:$P$2407=1)*(Data_Daily!$Q$2:$Q$2407-F44)^2)/(E44-1) -> 0.01487287 | H44: =(F44-C44)*100 -> 3.965829 | I44: =(F44-C44)/SQRT(D44/B44+G44/E44) -> 2.5758109 | J44: =(D44/B44+G44/E44)^2/((D44/B44)^2/(B44-1)+(G44/E44)^2/(E44-1)) -> 155.99587 | K44: =TDIST(ABS(I44),J44,2) -> 0.01093484 | L44: =IF(K44<0.05,IF(H44<0,"Significant DROP","Significant RISE"),"No change") -> Significant RISE
A45: s_5 | B45: =COUNTIFS(Data_Daily!$A$2:$A$2407,$A45,Data_Daily!$O$2:$O$2407,2020,Data_Daily!$P$2:$P$2407,1) -> 226 | C45: =AVERAGEIFS(Data_Daily!$Q$2:$Q$2407,Data_Daily!$A$2:$A$2407,$A45,Data_Daily!$O$2:$O$2407,2020,Data_Daily!$P$2:$P$2407,1) -> 0.55056967 | D45: =SUMPRODUCT((Data_Daily!$A$2:$A$2407=$A45)*(Data_Daily!$O$2:$O$2407=2020)*(Data_Daily!$P$2:$P$2407=1)*(Data_Daily!$Q$2:$Q$2407-C45)^2)/(B45-1) -> 0.043274945 | E45: =COUNTIFS(Data_Daily!$A$2:$A$2407,$A45,Data_Daily!$O$2:$O$2407,2021,Data_Daily!$P$2:$P$2407,1) -> 209 | F45: =AVERAGEIFS(Data_Daily!$Q$2:$Q$2407,Data_Daily!$A$2:$A$2407,$A45,Data_Daily!$O$2:$O$2407,2021,Data_Daily!$P$2:$P$2407,1) -> 0.58839255 | G45: =SUMPRODUCT((Data_Daily!$A$2:$A$2407=$A45)*(Data_Daily!$O$2:$O$2407=2021)*(Data_Daily!$P$2:$P$2407=1)*(Data_Daily!$Q$2:$Q$2407-F45)^2)/(E45-1) -> 0.027121384 | H45: =(F45-C45)*100 -> 3.7822888 | I45: =(F45-C45)/SQRT(D45/B45+G45/E45) -> 2.110248 | J45: =(D45/B45+G45/E45)^2/((D45/B45)^2/(B45-1)+(G45/E45)^2/(E45-1)) -> 423.10015 | K45: =TDIST(ABS(I45),J45,2) -> 0.035423567 | L45: =IF(K45<0.05,IF(H45<0,"Significant DROP","Significant RISE"),"No change") -> Significant RISE
...

Sheet I1_Solutions
A1: I1 - Solution selection matrix
A2: IMPROVE. Priority = Impact x (6 - Effort). Scores are team judgement (yellow).
A4: Root cause (from Analyze) | B4: Countermeasure | C4: Lean tool | D4: Impact 1-5 | E4: Effort 1-5 | F4: Priority | G4: Owner | H4: Wave
A5: Idle has no reason code | B5: Mandatory reason-code pop-up after 3 min idle; weekly idle Pareto | C5: Poka-Yoke (data) + visual mgmt | D5: 5 | E5: 2 | F5: =D5*(6-E5) -> 20 | G5: Shift leads + IT | H5: 1
A6: Night / weekend idle | B6: Staffing & handover standard work; pre-staged material before night shift | C6: Standard work + Kanban | D6: 5 | E6: 3 | F6: =D6*(6-E6) -> 15 | G6: Production mgr | H6: 1
A7: A_065 micro-stops (s_1) | B7: 5-day Kaizen blitz: observe 20 stops, fix trigger, CIL standard | C7: Kaizen + 5 Whys + CIL | D7: 4 | E7: 2 | F7: =D7*(6-E7) -> 16 | G7: Maint. + operators | H7: 1
A8: A_001 / A_006 long stops | B8: Error-proof the setup step, standard repair kit at the machine | C8: Poka-Yoke + 5S | D8: 3 | E8: 3 | F8: =D8*(6-E8) -> 9 | G8: Maintenance | H8: 2
A9: A_101 repeat stops (s_2/3/5) | B9: Horizontal expansion of the s_1 Kaizen method | C9: Kaizen (Yokoten) | D9: 3 | E9: 2 | F9: =D9*(6-E9) -> 12 | G9: CI engineer | H9: 2
A10: Long changeovers | B10: SMED: separate internal/external, pre-kitting, quick clamps | C10: SMED | D10: 3 | E10: 3 | F10: =D10*(6-E10) -> 9 | G10: Setup techs | H10: 2
A11: Speed loss (s_4) | B11: Rated-speed standard + CIL; review speed set-points | C11: 5S / TPM | D11: 3 | E11: 2 | F11: =D11*(6-E11) -> 12 | G11: Process eng. | H11: 2
A12: Material starvation risk | B12: Two-bin Kanban line-side; ROP/EOQ for supplier orders | C12: Kanban + inventory policy | D12: 3 | E12: 2 | F12: =D12*(6-E12) -> 12 | G12: Stores / planning | H12: 1

Sheet I2_OEE_Scenario
A1: I2 - Projected OEE bridge by Lean lever (edit the yellow reduction rates)
A2: IMPROVE. Recovered hours become run time at the current performance rate. These are PROJECTIONS - validate in the s_1 pilot.
A5: Planned production time (h) | B5: =M2_OEE!D10 -> 37596.355
A6: Run time (h) | B6: =M2_OEE!E10 -> 24182.954
A7: Performance | B7: =M2_OEE!M10 -> 0.80763044
A8: Quality | B8: =M2_OEE!N10 -> 0.99591163
A9: Idle (h) | B9: =M2_OEE!G10 -> 10265.964
A10: A_001 + A_006 downtime (h) | B10: =SUMIF(M4_Pareto!A:A,"A_001",M4_Pareto!C:C)+SUMIF(M4_Pareto!A:A,"A_006",M4_Pareto!C:C) -> 798.79671
A11: A_065 + A_101 + A_066 downtime (h) | B11: =SUMIF(M4_Pareto!A:A,"A_065",M4_Pareto!C:C)+SUMIF(M4_Pareto!A:A,"A_101",M4_Pareto!C:C)+SUMIF(M4_Pareto!A:A,"A_066",M4_Pareto!C:C) -> 1526.5401
A12: Other alarm downtime (h) | B12: =M2_OEE!F10-B10-B11 -> 822.09961
A13: Baseline OEE | B13: =B6*B7*B8/B5 -> 0.51736506
A15: Lever | B15: Lean tool | C15: Loss bucket (h) | D15: Assumed reduction | E15: Hours recovered | F15: Run time after (h) | G15: Performance after | H15: OEE after | I15: Delta (pts)
A16: Baseline | F16: =B6 -> 24182.954 | G16: =B7 -> 0.80763044 | H16: =F16*G16*$B$8/$B$5 -> 0.51736506
A17: Poka-Yoke + autonomous maintenance (A_001, A_006) | B17: Poka-Yoke / TPM | C17: =B10 -> 798.79671 | D17: 0.4 | E17: =C17*D17 -> 319.51869 | F17: =F16+E17 -> 24502.473 | G17: =G16 -> 0.80763044 | H17: =F17*G17*$B$8/$B$5 -> 0.52420077 | I17: =(H17-H16)*100 -> 0.68357159
A18: Kaizen blitz on micro-stops (A_065, A_101, A_066) | B18: Kaizen / 5 Whys | C18: =B11 -> 1526.5401 | D18: 0.3 | E18: =C18*D18 -> 457.96203 | F18: =F17+E18 -> 24960.435 | G18: =G17 -> 0.80763044 | H18: =F18*G18*$B$8/$B$5 -> 0.53399832 | I18: =(H18-H17)*100 -> 0.97975439
A19: 5S + visual management (other alarms) | B19: 5S | C19: =B12 -> 822.09961 | D19: 0.1 | E19: =C19*D19 -> 82.209961 | F19: =F18+E19 -> 25042.645 | G19: =G18 -> 0.80763044 | H19: =F19*G19*$B$8/$B$5 -> 0.5357571 | I19: =(H19-H18)*100 -> 0.17587827
A20: Idle recovery: reason codes + Kanban + night/weekend standard work | B20: Poka-Yoke (data) / Kanban / Std work | C20: =B9 -> 10265.964 | D20: 0.25 | E20: =C20*D20 -> 2566.4911 | F20: =F19+E20 -> 27609.136 | G20: =G19 -> 0.80763044 | H20: =F20*G20*$B$8/$B$5 -> 0.59066407 | I20: =(H20-H19)*100 -> 5.4906973
A21: CIL routine + rated-speed standard | B21: 5S / TPM | C21: =F20*(1-G20) -> 5311.1573 | D21: 0.2 | E21: =C21*D21 -> 1062.2315 | F21: =F20 -> 27609.136 | G21: =G20+(1-G20)*D21 -> 0.84610435 | H21: =F21*G21*$B$8/$B$5 -> 0.61880214 | I21: =(H21-H20)*100 -> 2.8138065
A22: PROJECTED OEE | H22: =H21 -> 0.61880214 | I22: =(H22-H16)*100 -> 10.143708
A25: Ideal packs per run-hour | B25: =M2_OEE!I10/M2_OEE!E10 -> 4892.6019 | D25: Blunt reading: the idle lever is worth more than all alarm levers combined. Classic 'fix the top alarm' Six Sigma would miss most of the prize.
A26: Extra good packs per year | B26: =(H22-H16)*B5*B25/Inputs!$B$8 -> 9329370.9
A27: Contribution gain (INR / year) | B27: =B26*Inputs!$B$7 -> 5597622.5
A28: Contribution gain (INR lakh / year) | B28: =B27/100000 -> 55.976225
A29: COPQ of rejects (INR / year) | B29: =(M2_OEE!J10-M2_OEE!K10)/Inputs!$B$8*Inputs!$B$7 -> 117201.6
A30: Packs lost vs ideal per year (all losses) | B30: =(1-H16)*B5*B25/Inputs!$B$8 -> 44388900

Sheet I3_SMED
A1: I3 - SMED: changeover reduction
A2: IMPROVE. Baseline from v_smed_baseline (planned stops 10 min - 4 h used as changeover proxy - ASSUMPTION).
A4: Machine | B4: Events | C4: Mean min | D4: Median min | E4: P90 min | F4: Hours | G4: Events / year | H4: Target mean min | I4: Hours released / year
A5: s_1 | B5: 1411 | C5: 36.621765 | D5: 24.845517 | E5: 58.701767 | F5: 861.22184 | G5: =B5/Inputs!$B$8 -> 705.5 | H5: =C5*(1-Inputs!$B$18) -> 21.973059 | I5: =F5/Inputs!$B$8*Inputs!$B$18 -> 172.24437
A6: s_2 | B6: 1489 | C6: 52.552337 | D6: 50.528217 | E6: 72.260587 | F6: 1304.1738 | G6: =B6/Inputs!$B$8 -> 744.5 | H6: =C6*(1-Inputs!$B$18) -> 31.531402 | I6: =F6/Inputs!$B$8*Inputs!$B$18 -> 260.83476
A7: s_3 | B7: 823 | C7: 43.900472 | D7: 15 | E7: 109.82877 | F7: 602.16815 | G7: =B7/Inputs!$B$8 -> 411.5 | H7: =C7*(1-Inputs!$B$18) -> 26.340283 | I7: =F7/Inputs!$B$8*Inputs!$B$18 -> 120.43363
A8: s_4 | B8: 642 | C8: 68.052163 | D8: 50.139167 | E8: 162.89771 | F8: 728.15814 | G8: =B8/Inputs!$B$8 -> 321 | H8: =C8*(1-Inputs!$B$18) -> 40.831298 | I8: =F8/Inputs!$B$8*Inputs!$B$18 -> 145.63163
A9: s_5 | B9: 1604 | C9: 60.395896 | D9: 38.977408 | E9: 166.76665 | F9: 1614.5836 | G9: =B9/Inputs!$B$8 -> 802 | H9: =C9*(1-Inputs!$B$18) -> 36.237538 | I9: =F9/Inputs!$B$8*Inputs!$B$18 -> 322.91672
A10: Fleet | B10: =SUM(B5:B9) -> 5969 | C10: =SUMPRODUCT(B5:B9,C5:C9)/B10 -> 51.368459 | F10: =SUM(F5:F9) -> 5110.3056 | I10: =SUM(I5:I9) -> 1022.0611
A12: SMED study template (TEMPLATE EXAMPLE - replace with a timed video study of one real changeover)
A13: # | B13: Element | C13: Current min | D13: Internal / External (now) | E13: Can it be external? | F13: Improvement idea | G13: Future min | H13: Future type
A14: 1 | B14: Stop machine, clear line | C14: 3 | D14: Internal | E14: No | F14: Standard stop sequence | G14: 2 | H14: Internal
A15: 2 | B15: Fetch new film reel / blanks from store | C15: 8 | D15: Internal | E15: Yes | F15: Pre-kit on trolley before stop (Kanban) | G15: 0 | H15: External
A16: 3 | B16: Fetch tools and change parts | C16: 6 | D16: Internal | E16: Yes | F16: Shadow board at machine (5S) | G16: 0 | H16: External
A17: 4 | B17: Remove old format parts | C17: 7 | D17: Internal | E17: No | F17: Quick-release clamps | G17: 4 | H17: Internal
A18: 5 | B18: Fit new format parts | C18: 8 | D18: Internal | E18: No | F18: Colour-coded, keyed parts (Poka-Yoke) | G18: 5 | H18: Internal
A19: 6 | B19: Adjust guides by trial and error | C19: 10 | D19: Internal | E19: No | F19: Fixed-position stops, no adjustment | G19: 3 | H19: Internal
A20: 7 | B20: First-off quality check | C20: 4 | D20: Internal | E20: No | F20: Go/no-go gauge | G20: 3 | H20: Internal
A21: 8 | B21: Paperwork / log entry | C21: 3 | D21: Internal | E21: Yes | F21: Do while running | G21: 0 | H21: External
B22: Total internal (machine stopped) minutes | C22: =SUMIF(D14:D21,"Internal",C14:C21) -> 49 | G22: =SUMIF(H14:H21,"Internal",G14:G21) -> 17
B23: Reduction | G23: =1-G22/C22 -> 0.65306122

Sheet I4_PokaYoke
A1: I4 - Poka-Yoke (error-proofing) plan
A2: IMPROVE. Alarm codes are anonymised, so devices are proposals to validate with maintenance.
A4: Failure mode / error | B4: Poka-Yoke device | C4: Type | D4: Function | E4: Verification
A5: Idle with no reason (data error) | B5: HMI forces a reason-code choice after 3 min idle; cannot restart without it | C5: Motion-step | D5: Control (prevent) | E5: % idle minutes coded >= 95%
A6: A_001 / A_006 long stops | B6: Keyed / colour-coded change parts that fit only one way | C6: Contact | D6: Control | E6: Stop count per 1,000 run-h
A7: A_065 jam at infeed (hyp.) | B7: Photo-eye detects mis-fed blank and diverts it before the jam | C7: Contact (sensor) | D7: Warning + divert | E7: A_065 stops per run-h
A8: Wrong material staged | B8: Barcode scan of film / blank lot vs work order before start | C8: Fixed-value | D8: Control | E8: Wrong-material incidents = 0
A9: Changeover step skipped | B9: Checklist on HMI with interlock until all steps confirmed | C9: Motion-step | D9: Control | E9: First-off pass rate
A10: Speed set below rated | B10: Speed set-point locked to recipe; override needs supervisor PIN | C10: Fixed-value | D10: Control | E10: Performance rate

Sheet I5_5S_Audit
A1: I5 - 5S audit (score 0-4, yellow cells)
A2: IMPROVE / CONTROL. Audit weekly in the pilot, monthly after.
A4: S | B4: Audit question | C4: Score (0-4)
A5: Sort | B5: Only items needed for the current format are at the machine | C5: 3
A6: Sort | B6: Red-tag area exists and is cleared weekly | C6: 2
A7: Set in order | B7: Shadow board for changeover tools; every tool has a home | C7: 2
A8: Set in order | B8: Kanban bins labelled with qty and location | C8: 1
A9: Shine | B9: Cleaning = inspection: CIL checklist done every shift | C9: 1
A10: Shine | B10: Sources of dust / glue / film scrap identified and contained | C10: 2
A11: Standardise | B11: One-point lessons posted for top 3 alarms | C11: 1
A12: Standardise | B12: Changeover standard (SMED) displayed and followed | C12: 1
A13: Sustain | B13: Audit done on schedule with actions tracked | C13: 2
A14: Sustain | B14: Shift handover includes OEE and idle reasons | C14: 1
A16: S | B16: Score %
A17: Sort | B17: =SUMIF($A$5:$A$14,A17,$C$5:$C$14)/(COUNTIF($A$5:$A$14,A17)*4) -> 0.625
A18: Set in order | B18: =SUMIF($A$5:$A$14,A18,$C$5:$C$14)/(COUNTIF($A$5:$A$14,A18)*4) -> 0.375
A19: Shine | B19: =SUMIF($A$5:$A$14,A19,$C$5:$C$14)/(COUNTIF($A$5:$A$14,A19)*4) -> 0.375
A20: Standardise | B20: =SUMIF($A$5:$A$14,A20,$C$5:$C$14)/(COUNTIF($A$5:$A$14,A20)*4) -> 0.25
A21: Sustain | B21: =SUMIF($A$5:$A$14,A21,$C$5:$C$14)/(COUNTIF($A$5:$A$14,A21)*4) -> 0.375
A22: Overall 5S score | B22: =SUM(C5:C14)/(COUNT(C5:C14)*4) -> 0.4
A23: Example scores shown - replace with your own audit.

Sheet I6_Kaizen
A1: I6 - Kaizen event (5-day blitz on A_065, s_1) + PDCA tracker
A2: IMPROVE.
A4: Day | B4: Activity | C4: Output
A5: Day 1 | B5: Train team; review Pareto/FMEA; walk the line; set target (-30% A_065 hours) | C5: Kaizen charter
A6: Day 2 | B6: Observe and video 20+ A_065 stops; 5 Whys on each; tag triggers | C6: Cause list with evidence
A7: Day 3 | B7: Try fixes on the machine (adjust, clean, guide, sensor); SMED on recovery | C7: Tested countermeasures
